Workbook

Sheet Données
A1: Presses | C1: Code Article | D1: Désig Article | E1: Tps de cycle (s)
A2: D140.1 | C2: 2.1.30171 | D2: Cover KIKO | E2: =39/8 -> 4.875
A3: D180.1 | C3: 2.1.30172 | D3: Base KIKO | E3: =38/8 -> 4.75
A4: D230.1 | C4: 2.1.30173 | D4: Insert KIKO | E4: =30/8 -> 3.75
A5: D230.2
A6: D230.3
A7: D230.4
A8: D280.1
A9: D280.2
A10: D280.3
A11: D280.4
A12: F220.1
A13: F220.2
A14: F220.3
A15: F220.4
A16: F150.1
A17: F150.2

Sheet Saisie_Donnees
A1: ATELIER INJECTION PLASTIQUE
A3: Date | B3: Poste | C3: Presse | D3: Code Moule | E3: Désignation Article | F3: Temps Ouv. (min) | G3: Arrêts Planif. (min) | H3: Temps Req. (min) | I3: Pannes (min) | J3: temps de dém/arrêt (min) | K3: Chgt Moule (min) | L3: Temps Mach. (min) | M3: Qté Totale (pcs) | N3: Qté Conforme (pcs) | O3: Rebuts Dém / Réglage (pcs) | P3: Rebuts Prod (pcs) | Q3: Cycle Théo (s) | R3: Taux Disp. (Td) | S3: Taux Perf. (Tp) | T3: Taux Qual. (Tq) | U3: TRS | V3: Temps standards (s) | W3: Nbre d'heures dépensées (h) | X3: Recette (h) | Y3: DLE (%)
A4: 46296 | B4: Nuit | C4: D140.1 | D4: 2.1.30173 | E4: =VLOOKUP(D4,Données!$C$2:$D$1300,2,FALSE) -> Insert KIKO | F4: 480 | G4: 480 | H4: =F4-G4 -> 0 | I4: 0 | K4: 0 | L4: =H4-I4-J4-K4 -> 0 | M4: =+N4+O4+P4 -> 0 | N4: 0 | O4: 0 | P4: 0 | Q4: =VLOOKUP(D4,Données!$C$2:$E$1300,3,FALSE) -> 3.75 | R4: =IF(H4>0,L4/H4,"") | S4: =IF(L4=0,"",M4/(L4*60/Q4)) | T4: =IF(M4>0,N4/M4,"") | U4: =IF(H4>0,R4*S4*T4,"") | V4: =VLOOKUP(D4,Données!$C$2:$E$1300,3,FALSE) -> 3.75 | W4: 0 | X4: =+V4*N4/3600 -> 0 | Y4: =IF(W4=0,"",X4/W4)
A5: 46296 | B5: Nuit | C5: D230.1 | D5: 2.1.30172 | E5: =VLOOKUP(D5,Données!$C$2:$D$1300,2,FALSE) -> Base KIKO | F5: 480 | G5: 480 | H5: =F5-G5 -> 0 | I5: 0 | K5: 0 | L5: =H5-I5-J5-K5 -> 0 | M5: =+N5+O5+P5 -> 0 | N5: 0 | O5: 0 | P5: 0 | Q5: =VLOOKUP(D5,Données!$C$2:$E$1300,3,FALSE) -> 4.75 | R5: =IF(H5>0,L5/H5,"") | S5: =IF(L5=0,"",M5/(L5*60/Q5)) | T5: =IF(M5>0,N5/M5,"") | U5: =IF(H5>0,R5*S5*T5,"") | V5: =VLOOKUP(D5,Données!$C$2:$E$1300,3,FALSE) -> 4.75 | W5: 0 | X5: =+V5*N5/3600 -> 0 | Y5: =IF(W5=0,"",X5/W5)
A6: 46296 | B6: Nuit | C6: D230.3 | D6: 2.1.30171 | E6: =VLOOKUP(D6,Données!$C$2:$D$1300,2,FALSE) -> Cover KIKO | F6: 480 | G6: 480 | H6: =F6-G6 -> 0 | I6: 0 | K6: 0 | L6: =H6-I6-J6-K6 -> 0 | M6: =+N6+O6+P6 -> 0 | N6: 0 | O6: 0 | P6: 0 | Q6: =VLOOKUP(D6,Données!$C$2:$E$1300,3,FALSE) -> 4.875 | R6: =IF(H6>0,L6/H6,"") | S6: =IF(L6=0,"",M6/(L6*60/Q6)) | T6: =IF(M6>0,N6/M6,"") | U6: =IF(H6>0,R6*S6*T6,"") | V6: =VLOOKUP(D6,Données!$C$2:$E$1300,3,FALSE) -> 4.875 | W6: 0 | X6: =+V6*N6/3600 -> 0 | Y6: =IF(W6=0,"",X6/W6)
A7: 46296 | B7: Matin | C7: D140.1 | D7: 2.1.30173 | E7: =VLOOKUP(D7,Données!$C$2:$D$1300,2,FALSE) -> Insert KIKO | F7: 480 | H7: =F7-G7 -> 480 | I7: 0 | J7: 45 | K7: 0 | L7: =H7-I7-J7-K7 -> 435 | M7: =+N7+O7+P7 -> 2840 | N7: 2820 | O7: 20 | P7: 0 | Q7: =VLOOKUP(D7,Données!$C$2:$E$1300,3,FALSE) -> 3.75 | R7: =IF(H7>0,L7/H7,"") -> 0.90625 | S7: =IF(L7=0,"",M7/(L7*60/Q7)) -> 0.40804598 | T7: =IF(M7>0,N7/M7,"") -> 0.99295775 | U7: =IF(H7>0,R7*S7*T7,"") -> 0.3671875 | V7: =VLOOKUP(D7,Données!$C$2:$E$1300,3,FALSE) -> 3.75 | W7: 8 | X7: =+V7*N7/3600 -> 2.9375 | Y7: =IF(W7=0,"",X7/W7) -> 0.3671875
A8: 46296 | B8: Matin | C8: D230.1 | D8: 2.1.30172 | E8: =VLOOKUP(D8,Données!$C$2:$D$1300,2,FALSE) -> Base KIKO | F8: 480 | H8: =F8-G8 -> 480 | I8: 0 | J8: 45 | K8: 0 | L8: =H8-I8-J8-K8 -> 435 | M8: =+N8+O8+P8 -> 3067 | N8: 3053 | O8: 14 | P8: 0 | Q8: =VLOOKUP(D8,Données!$C$2:$E$1300,3,FALSE) -> 4.75 | R8: =IF(H8>0,L8/H8,"") -> 0.90625 | S8: =IF(L8=0,"",M8/(L8*60/Q8)) -> 0.5581705 | T8: =IF(M8>0,N8/M8,"") -> 0.99543528 | U8: =IF(H8>0,R8*S8*T8,"") -> 0.50353299 | V8: =VLOOKUP(D8,Données!$C$2:$E$1300,3,FALSE) -> 4.75 | W8: 8 | X8: =+V8*N8/3600 -> 4.0282639 | Y8: =IF(W8=0,"",X8/W8) -> 0.50353299
A9: 46296 | B9: Matin | C9: D230.3 | D9: 2.1.30171 | E9: =VLOOKUP(D9,Données!$C$2:$D$1300,2,FALSE) -> Cover KIKO | F9: 480 | H9: =F9-G9 -> 480 | I9: 0 | J9: 45 | K9: 0 | L9: =H9-I9-J9-K9 -> 435 | M9: =+N9+O9+P9 -> 4363 | N9: 4341 | O9: 22 | P9: 0 | Q9: =VLOOKUP(D9,Données!$C$2:$E$1300,3,FALSE) -> 4.875 | R9: =IF(H9>0,L9/H9,"") -> 0.90625 | S9: =IF(L9=0,"",M9/(L9*60/Q9)) -> 0.81492816 | T9: =IF(M9>0,N9/M9,"") -> 0.9949576 | U9: =IF(H9>0,R9*S9*T9,"") -> 0.73480469 | V9: =VLOOKUP(D9,Données!$C$2:$E$1300,3,FALSE) -> 4.875 | W9: 8 | X9: =+V9*N9/3600 -> 5.8784375 | Y9: =IF(W9=0,"",X9/W9) -> 0.73480469
A10: 46296 | B10: Après-Midi | C10: D140.1 | D10: 2.1.30173 | E10: =VLOOKUP(D10,Données!$C$2:$D$1300,2,FALSE) -> Insert KIKO | F10: 480 | H10: =F10-G10 -> 480 | I10: 0 | J10: 25 | K10: 0 | L10: =H10-I10-J10-K10 -> 455 | M10: =+N10+O10+P10 -> 5784 | N10: 5761 | O10: 23 | P10: 0 | Q10: =VLOOKUP(D10,Données!$C$2:$E$1300,3,FALSE) -> 3.75 | R10: =IF(H10>0,L10/H10,"") -> 0.94791667 | S10: =IF(L10=0,"",M10/(L10*60/Q10)) -> 0.79450549 | T10: =IF(M10>0,N10/M10,"") -> 0.99602351 | U10: =IF(H10>0,R10*S10*T10,"") -> 0.75013021 | V10: =VLOOKUP(D10,Données!$C$2:$E$1300,3,FALSE) -> 3.75 | W10: 8 | X10: =+V10*N10/3600 -> 6.0010417 | Y10: =IF(W10=0,"",X10/W10) -> 0.75013021
A11: 46296 | B11: Après-Midi | C11: D230.1 | D11: 2.1.30172 | E11: =VLOOKUP(D11,Données!$C$2:$D$1300,2,FALSE) -> Base KIKO | F11: 480 | H11: =F11-G11 -> 480 | I11: 0 | J11: 25 | K11: 0 | L11: =H11-I11-J11-K11 -> 455 | M11: =+N11+O11+P11 -> 5509 | N11: 5498 | O11: 11 | P11: 0 | Q11: =VLOOKUP(D11,Données!$C$2:$E$1300,3,FALSE) -> 4.75 | R11: =IF(H11>0,L11/H11,"") -> 0.94791667 | S11: =IF(L11=0,"",M11/(L11*60/Q11)) -> 0.95852564 | T11: =IF(M11>0,N11/M11,"") -> 0.99800327 | U11: =IF(H11>0,R11*S11*T11,"") -> 0.90678819 | V11: =VLOOKUP(D11,Données!$C$2:$E$1300,3,FALSE) -> 4.75 | W11: 8 | X11: =+V11*N11/3600 -> 7.2543056 | Y11: =IF(W11=0,"",X11/W11) -> 0.90678819
A12: 46296 | B12: Après-Midi | C12: D230.3 | D12: 2.1.30171 | E12: =VLOOKUP(D12,Données!$C$2:$D$1300,2,FALSE) -> Cover KIKO | F12: 480 | H12: =F12-G12 -> 480 | I12: 0 | J12: 25 | K12: 0 | L12: =H12-I12-J12-K12 -> 455 | M12: =+N12+O12+P12 -> 6142 | N12: 6138 | O12: 4 | P12: 0 | Q12: =VLOOKUP(D12,Données!$C$2:$E$1300,3,FALSE) -> 4.875 | R12: =IF(H12>0,L12/H12,"") -> 0.94791667 | S12: =IF(L12=0,"",M12/(L12*60/Q12)) -> 1.0967857 | T12: =IF(M12>0,N12/M12,"") -> 0.99934875 | U12: =IF(H12>0,R12*S12*T12,"") -> 1.0389844 | V12: =VLOOKUP(D12,Données!$C$2:$E$1300,3,FALSE) -> 4.875 | W12: 8 | X12: =+V12*N12/3600 -> 8.311875 | Y12: =IF(W12=0,"",X12/W12) -> 1.0389844
A13: 46297 | B13: Nuit | C13: D140.1 | D13: 2.1.30173 | E13: =VLOOKUP(D13,Données!$C$2:$D$1300,2,FALSE) -> Insert KIKO | F13: 480 | G13: 480 | H13: =F13-G13 -> 0 | I13: 0 | K13: 0 | L13: =H13-I13-J13-K13 -> 0 | M13: =+N13+O13+P13 -> 0 | N13: 0 | O13: 0 | P13: 0 | Q13: =VLOOKUP(D13,Données!$C$2:$E$1300,3,FALSE) -> 3.75 | R13: =IF(H13>0,L13/H13,"") | S13: =IF(L13=0,"",M13/(L13*60/Q13)) | T13: =IF(M13>0,N13/M13,"") | U13: =IF(H13>0,R13*S13*T13,"") | V13: =VLOOKUP(D13,Données!$C$2:$E$1300,3,FALSE) -> 3.75 | W13: 0 | X13: =+V13*N13/3600 -> 0 | Y13: =IF(W13=0,"",X13/W13)
A14: 46297 | B14: Nuit | C14: D230.1 | D14: 2.1.30172 | E14: =VLOOKUP(D14,Données!$C$2:$D$1300,2,FALSE) -> Base KIKO | F14: 480 | G14: 480 | H14: =F14-G14 -> 0 | I14: 0 | K14: 0 | L14: =H14-I14-J14-K14 -> 0 | M14: =+N14+O14+P14 -> 0 | N14: 0 | O14: 0 | P14: 0 | Q14: =VLOOKUP(D14,Données!$C$2:$E$1300,3,FALSE) -> 4.75 | R14: =IF(H14>0,L14/H14,"") | S14: =IF(L14=0,"",M14/(L14*60/Q14)) | T14: =IF(M14>0,N14/M14,"") | U14: =IF(H14>0,R14*S14*T14,"") | V14: =VLOOKUP(D14,Données!$C$2:$E$1300,3,FALSE) -> 4.75 | W14: 0 | X14: =+V14*N14/3600 -> 0 | Y14: =IF(W14=0,"",X14/W14)
A15: 46297 | B15: Nuit | C15: D230.3 | D15: 2.1.30171 | E15: =VLOOKUP(D15,Données!$C$2:$D$1300,2,FALSE) -> Cover KIKO | F15: 480 | G15: 480 | H15: =F15-G15 -> 0 | I15: 0 | K15: 0 | L15: =H15-I15-J15-K15 -> 0 | M15: =+N15+O15+P15 -> 0 | N15: 0 | O15: 0 | P15: 0 | Q15: =VLOOKUP(D15,Données!$C$2:$E$1300,3,FALSE) -> 4.875 | R15: =IF(H15>0,L15/H15,"") | S15: =IF(L15=0,"",M15/(L15*60/Q15)) | T15: =IF(M15>0,N15/M15,"") | U15: =IF(H15>0,R15*S15*T15,"") | V15: =VLOOKUP(D15,Données!$C$2:$E$1300,3,FALSE) -> 4.875 | W15: 0 | X15: =+V15*N15/3600 -> 0 | Y15: =IF(W15=0,"",X15/W15)
A16: 46297 | B16: Matin | C16: D140.1 | D16: 2.1.30173 | E16: =VLOOKUP(D16,Données!$C$2:$D$1300,2,FALSE) -> Insert KIKO | F16: 480 | H16: =F16-G16 -> 480 | I16: 0 | J16: 45 | K16: 0 | L16: =H16-I16-J16-K16 -> 435 | M16: =+N16+O16+P16 -> 4139 | N16: 4093 | O16: 46 | P16: 0 | Q16: =VLOOKUP(D16,Données!$C$2:$E$1300,3,FALSE) -> 3.75 | R16: =IF(H16>0,L16/H16,"") -> 0.90625 | S16: =IF(L16=0,"",M16/(L16*60/Q16)) -> 0.59468391 | T16: =IF(M16>0,N16/M16,"") -> 0.9888862 | U16: =IF(H16>0,R16*S16*T16,"") -> 0.53294271 | V16: =VLOOKUP(D16,Données!$C$2:$E$1300,3,FALSE) -> 3.75 | W16: 8 | X16: =+V16*N16/3600 -> 4.2635417 | Y16: =IF(W16=0,"",X16/W16) -> 0.53294271
A17: 46297 | B17: Matin | C17: D230.1 | D17: 2.1.30172 | E17: =VLOOKUP(D17,Données!$C$2:$D$1300,2,FALSE) -> Base KIKO | F17: 480 | H17: =F17-G17 -> 480 | I17: 0 | J17: 45 | K17: 0 | L17: =H17-I17-J17-K17 -> 435 | M17: =+N17+O17+P17 -> 4807 | N17: 4740 | O17: 67 | P17: 0 | Q17: =VLOOKUP(D17,Données!$C$2:$E$1300,3,FALSE) -> 4.75 | R17: =IF(H17>0,L17/H17,"") -> 0.90625 | S17: =IF(L17=0,"",M17/(L17*60/Q17)) -> 0.87483716 | T17: =IF(M17>0,N17/M17,"") -> 0.98606199 | U17: =IF(H17>0,R17*S17*T17,"") -> 0.78177083 | V17: =VLOOKUP(D17,Données!$C$2:$E$1300,3,FALSE) -> 4.75 | W17: 8 | X17: =+V17*N17/3600 -> 6.2541667 | Y17: =IF(W17=0,"",X17/W17) -> 0.78177083
A18: 46297 | B18: Matin | C18: D230.3 | D18: 2.1.30171 | E18: =VLOOKUP(D18,Données!$C$2:$D$1300,2,FALSE) -> Cover KIKO | F18: 480 | H18: =F18-G18 -> 480 | I18: 0 | J18: 45 | K18: 0 | L18: =H18-I18-J18-K18 -> 435 | M18: =+N18+O18+P18 -> 4616 | N18: 4596 | O18: 20 | P18: 0 | Q18: =VLOOKUP(D18,Données!$C$2:$E$1300,3,FALSE) -> 4.875 | R18: =IF(H18>0,L18/H18,"") -> 0.90625 | S18: =IF(L18=0,"",M18/(L18*60/Q18)) -> 0.86218391 | T18: =IF(M18>0,N18/M18,"") -> 0.99566724 | U18: =IF(H18>0,R18*S18*T18,"") -> 0.77796875 | V18: =VLOOKUP(D18,Données!$C$2:$E$1300,3,FALSE) -> 4.875 | W18: 8 | X18: =+V18*N18/3600 -> 6.22375 | Y18: =IF(W18=0,"",X18/W18) -> 0.77796875
A19: 46297 | B19: Après-Midi | C19: D140.1 | D19: 2.1.30173 | E19: =VLOOKUP(D19,Données!$C$2:$D$1300,2,FALSE) -> Insert KIKO | F19: 480 | H19: =F19-G19 -> 480 | I19: 0 | J19: 25 | K19: 0 | L19: =H19-I19-J19-K19 -> 455 | M19: =+N19+O19+P19 -> 6526 | N19: 6474 | O19: 52 | P19: 0 | Q19: =VLOOKUP(D19,Données!$C$2:$E$1300,3,FALSE) -> 3.75 | R19: =IF(H19>0,L19/H19,"") -> 0.94791667 | S19: =IF(L19=0,"",M19/(L19*60/Q19)) -> 0.89642857 | T19: =IF(M19>0,N19/M19,"") -> 0.99203187 | U19: =IF(H19>0,R19*S19*T19,"") -> 0.84296875 | V19: =VLOOKUP(D19,Données!$C$2:$E$1300,3,FALSE) -> 3.75 | W19: 8 | X19: =+V19*N19/3600 -> 6.74375 | Y19: =IF(W19=0,"",X19/W19) -> 0.84296875
A20: 46297 | B20: Après-Midi | C20: D230.1 | D20: 2.1.30172 | E20: =VLOOKUP(D20,Données!$C$2:$D$1300,2,FALSE) -> Base KIKO | F20: 480 | H20: =F20-G20 -> 480 | I20: 0 | J20: 25 | K20: 0 | L20: =H20-I20-J20-K20 -> 455 | M20: =+N20+O20+P20 -> 6442 | N20: 6402 | O20: 40 | P20: 0 | Q20: =VLOOKUP(D20,Données!$C$2:$E$1300,3,FALSE) -> 4.75 | R20: =IF(H20>0,L20/H20,"") -> 0.94791667 | S20: =IF(L20=0,"",M20/(L20*60/Q20)) -> 1.1208608 | T20: =IF(M20>0,N20/M20,"") -> 0.99379075 | U20: =IF(H20>0,R20*S20*T20,"") -> 1.0558854 | V20: =VLOOKUP(D20,Données!$C$2:$E$1300,3,FALSE) -> 4.75 | W20: 8 | X20: =+V20*N20/3600 -> 8.4470833 | Y20: =IF(W20=0,"",X20/W20) -> 1.0558854
A21: 46297 | B21: Après-Midi | C21: D230.3 | D21: 2.1.30171 | E21: =VLOOKUP(D21,Données!$C$2:$D$1300,2,FALSE) -> Cover KIKO | F21: 480 | H21: =F21-G21 -> 480 | I21: 0 | J21: 25 | K21: 0 | L21: =H21-I21-J21-K21 -> 455 | M21: =+N21+O21+P21 -> 4400 | N21: 4394 | O21: 6 | P21: 0 | Q21: =VLOOKUP(D21,Données!$C$2:$E$1300,3,FALSE) -> 4.875 | R21: =IF(H21>0,L21/H21,"") -> 0.94791667 | S21: =IF(L21=0,"",M21/(L21*60/Q21)) -> 0.78571429 | T21: =IF(M21>0,N21/M21,"") -> 0.99863636 | U21: =IF(H21>0,R21*S21*T21,"") -> 0.74377604 | V21: =VLOOKUP(D21,Données!$C$2:$E$1300,3,FALSE) -> 4.875 | W21: 8 | X21: =+V21*N21/3600 -> 5.9502083 | Y21: =IF(W21=0,"",X21/W21) -> 0.74377604
A22: 46298 | B22: Nuit | C22: D140.1 | D22: 2.1.30173 | E22: =VLOOKUP(D22,Données!$C$2:$D$1300,2,FALSE) -> Insert KIKO | F22: 480 | G22: 480 | H22: =F22-G22 -> 0 | I22: 0 | K22: 0 | L22: =H22-I22-J22-K22 -> 0 | M22: =+N22+O22+P22 -> 0 | N22: 0 | O22: 0 | P22: 0 | Q22: =VLOOKUP(D22,Données!$C$2:$E$1300,3,FALSE) -> 3.75 | R22: =IF(H22>0,L22/H22,"") | S22: =IF(L22=0,"",M22/(L22*60/Q22)) | T22: =IF(M22>0,N22/M22,"") | U22: =IF(H22>0,R22*S22*T22,"") | V22: =VLOOKUP(D22,Données!$C$2:$E$1300,3,FALSE) -> 3.75 | W22: 0 | X22: =+V22*N22/3600 -> 0 | Y22: =IF(W22=0,"",X22/W22)
A23: 46298 | B23: Nuit | C23: D230.1 | D23: 2.1.30172 | E23: =VLOOKUP(D23,Données!$C$2:$D$1300,2,FALSE) -> Base KIKO | F23: 480 | G23: 480 | H23: =F23-G23 -> 0 | I23: 0 | K23: 0 | L23: =H23-I23-J23-K23 -> 0 | M23: =+N23+O23+P23 -> 0 | N23: 0 | O23: 0 | P23: 0 | Q23: =VLOOKUP(D23,Données!$C$2:$E$1300,3,FALSE) -> 4.75 | R23: =IF(H23>0,L23/H23,"") | S23: =IF(L23=0,"",M23/(L23*60/Q23)) | T23: =IF(M23>0,N23/M23,"") | U23: =IF(H23>0,R23*S23*T23,"") | V23: =VLOOKUP(D23,Données!$C$2:$E$1300,3,FALSE) -> 4.75 | W23: 0 | X23: =+V23*N23/3600 -> 0 | Y23: =IF(W23=0,"",X23/W23)
A24: 46298 | B24: Nuit | C24: D230.3 | D24: 2.1.30171 | E24: =VLOOKUP(D24,Données!$C$2:$D$1300,2,FALSE) -> Cover KIKO | F24: 480 | G24: 480 | H24: =F24-G24 -> 0 | I24: 0 | K24: 0 | L24: =H24-I24-J24-K24 -> 0 | M24: =+N24+O24+P24 -> 0 | N24: 0 | O24: 0 | P24: 0 | Q24: =VLOOKUP(D24,Données!$C$2:$E$1300,3,FALSE) -> 4.875 | R24: =IF(H24>0,L24/H24,"") | S24: =IF(L24=0,"",M24/(L24*60/Q24)) | T24: =IF(M24>0,N24/M24,"") | U24: =IF(H24>0,R24*S24*T24,"") | V24: =VLOOKUP(D24,Données!$C$2:$E$1300,3,FALSE) -> 4.875 | W24: 0 | X24: =+V24*N24/3600 -> 0 | Y24: =IF(W24=0,"",X24/W24)
A25: 46298 | B25: Matin | C25: D140.1 | D25: 2.1.30173 | E25: =VLOOKUP(D25,Données!$C$2:$D$1300,2,FALSE) -> Insert KIKO | F25: 480 | H25: =F25-G25 -> 480 | I25: 0 | J25: 45 | K25: 0 | L25: =H25-I25-J25-K25 -> 435 | M25: =+N25+O25+P25 -> 5782 | N25: 5776 | O25: 6 | P25: 0 | Q25: =VLOOKUP(D25,Données!$C$2:$E$1300,3,FALSE) -> 3.75 | R25: =IF(H25>0,L25/H25,"") -> 0.90625 | S25: =IF(L25=0,"",M25/(L25*60/Q25)) -> 0.83074713 | T25: =IF(M25>0,N25/M25,"") -> 0.9989623 | U25: =IF(H25>0,R25*S25*T25,"") -> 0.75208333 | V25: =VLOOKUP(D25,Données!$C$2:$E$1300,3,FALSE) -> 3.75 | W25: 8 | X25: =+V25*N25/3600 -> 6.0166667 | Y25: =IF(W25=0,"",X25/W25) -> 0.75208333
A26: 46298 | B26: Matin | C26: D230.1 | D26: 2.1.30172 | E26: =VLOOKUP(D26,Données!$C$2:$D$1300,2,FALSE) -> Base KIKO | F26: 480 | H26: =F26-G26 -> 480 | I26: 0 | J26: 45 | K26: 0 | L26: =H26-I26-J26-K26 -> 435 | M26: =+N26+O26+P26 -> 4623 | N26: 4594 | O26: 29 | P26: 0 | Q26: =VLOOKUP(D26,Données!$C$2:$E$1300,3,FALSE) -> 4.75 | R26: =IF(H26>0,L26/H26,"") -> 0.90625 | S26: =IF(L26=0,"",M26/(L26*60/Q26)) -> 0.84135057 | T26: =IF(M26>0,N26/M26,"") -> 0.99372702 | U26: =IF(H26>0,R26*S26*T26,"") -> 0.75769097 | V26: =VLOOKUP(D26,Données!$C$2:$E$1300,3,FALSE) -> 4.75 | W26: 8 | X26: =+V26*N26/3600 -> 6.0615278 | Y26: =IF(W26=0,"",X26/W26) -> 0.75769097
A27: 46298 | B27: Matin | C27: D230.3 | D27: 2.1.30171 | E27: =VLOOKUP(D27,Données!$C$2:$D$1300,2,FALSE) -> Cover KIKO | F27: 480 | H27: =F27-G27 -> 480 | I27: 0 | J27: 45 | K27: 0 | L27: =H27-I27-J27-K27 -> 435 | M27: =+N27+O27+P27 -> 6038 | N27: 6012 | O27: 26 | P27: 0 | Q27: =VLOOKUP(D27,Données!$C$2:$E$1300,3,FALSE) -> 4.875 | R27: =IF(H27>0,L27/H27,"") -> 0.90625 | S27: =IF(L27=0,"",M27/(L27*60/Q27)) -> 1.1277874 | T27: =IF(M27>0,N27/M27,"") -> 0.99569394 | U27: =IF(H27>0,R27*S27*T27,"") -> 1.0176562 | V27: =VLOOKUP(D27,Données!$C$2:$E$1300,3,FALSE) -> 4.875 | W27: 8 | X27: =+V27*N27/3600 -> 8.14125 | Y27: =IF(W27=0,"",X27/W27) -> 1.0176562
A28: 46298 | B28: Après-Midi | C28: D140.1 | D28: 2.1.30173 | E28: =VLOOKUP(D28,Données!$C$2:$D$1300,2,FALSE) -> Insert KIKO | F28: 480 | H28: =F28-G28 -> 480 | I28: 0 | J28: 25 | K28: 0 | L28: =H28-I28-J28-K28 -> 455 | M28: =+N28+O28+P28 -> 7271 | N28: 7244 | O28: 27 | P28: 0 | Q28: =VLOOKUP(D28,Données!$C$2:$E$1300,3,FALSE) -> 3.75 | R28: =IF(H28>0,L28/H28,"") -> 0.94791667 | S28: =IF(L28=0,"",M28/(L28*60/Q28)) -> 0.99876374 | T28: =IF(M28>0,N28/M28,"") -> 0.99628662 | U28: =IF(H28>0,R28*S28*T28,"") -> 0.94322917 | V28: =VLOOKUP(D28,Données!$C$2:$E$1300,3,FALSE) -> 3.75 | W28: 8 | X28: =+V28*N28/3600 -> 7.5458333 | Y28: =IF(W28=0,"",X28/W28) -> 0.94322917
A29: 46298 | B29: Après-Midi | C29: D230.1 | D29: 2.1.30172 | E29: =VLOOKUP(D29,Données!$C$2:$D$1300,2,FALSE) -> Base KIKO | F29: 480 | H29: =F29-G29 -> 480 | I29: 0 | J29: 25 | K29: 0 | L29: =H29-I29-J29-K29 -> 455 | M29: =+N29+O29+P29 -> 6366 | N29: 6346 | O29: 20 | P29: 0 | Q29: =VLOOKUP(D29,Données!$C$2:$E$1300,3,FALSE) -> 4.75 | R29: =IF(H29>0,L29/H29,"") -> 0.94791667 | S29: =IF(L29=0,"",M29/(L29*60/Q29)) -> 1.1076374 | T29: =IF(M29>0,N29/M29,"") -> 0.99685831 | U29: =IF(H29>0,R29*S29*T29,"") -> 1.0466493 | V29: =VLOOKUP(D29,Données!$C$2:$E$1300,3,FALSE) -> 4.75 | W29: 8 | X29: =+V29*N29/3600 -> 8.3731944 | Y29: =IF(W29=0,"",X29/W29) -> 1.0466493
A30: 46298 | B30: Après-Midi | C30: D230.3 | D30: 2.1.30171 | E30: =VLOOKUP(D30,Données!$C$2:$D$1300,2,FALSE) -> Cover KIKO | F30: 480 | H30: =F30-G30 -> 480 | I30: 0 | J30: 25 | K30: 0 | L30: =H30-I30-J30-K30 -> 455 | M30: =+N30+O30+P30 -> 6092 | N30: 6079 | O30: 13 | P30: 0 | Q30: =VLOOKUP(D30,Données!$C$2:$E$1300,3,FALSE) -> 4.875 | R30: =IF(H30>0,L30/H30,"") -> 0.94791667 | S30: =IF(L30=0,"",M30/(L30*60/Q30)) -> 1.0878571 | T30: =IF(M30>0,N30/M30,"") -> 0.99786605 | U30: =IF(H30>0,R30*S30*T30,"") -> 1.0289974 | V30: =VLOOKUP(D30,Données!$C$2:$E$1300,3,FALSE) -> 4.875 | W30: 8 | X30: =+V30*N30/3600 -> 8.2319792 | Y30: =IF(W30=0,"",X30/W30) -> 1.0289974
A31: 46300 | B31: Nuit | C31: D140.1 | D31: 2.1.30173 | E31: =VLOOKUP(D31,Données!$C$2:$D$1300,2,FALSE) -> Insert KIKO | F31: 480 | G31: 480 | H31: =F31-G31 -> 0 | I31: 0 | K31: 0 | L31: =H31-I31-J31-K31 -> 0 | M31: =+N31+O31+P31 -> 0 | N31: 0 | O31: 0 | P31: 0 | Q31: =VLOOKUP(D31,Données!$C$2:$E$1300,3,FALSE) -> 3.75 | R31: =IF(H31>0,L31/H31,"") | S31: =IF(L31=0,"",M31/(L31*60/Q31)) | T31: =IF(M31>0,N31/M31,"") | U31: =IF(H31>0,R31*S31*T31,"") | V31: =VLOOKUP(D31,Données!$C$2:$E$1300,3,FALSE) -> 3.75 | W31: 0 | X31: =+V31*N31/3600 -> 0 | Y31: =IF(W31=0,"",X31/W31)
A32: 46300 | B32: Nuit | C32: D230.1 | D32: 2.1.30172 | E32: =VLOOKUP(D32,Données!$C$2:$D$1300,2,FALSE) -> Base KIKO | F32: 480 | G32: 480 | H32: =F32-G32 -> 0 | I32: 0 | K32: 0 | L32: =H32-I32-J32-K32 -> 0 | M32: =+N32+O32+P32 -> 0 | N32: 0 | O32: 0 | P32: 0 | Q32: =VLOOKUP(D32,Données!$C$2:$E$1300,3,FALSE) -> 4.75 | R32: =IF(H32>0,L32/H32,"") | S32: =IF(L32=0,"",M32/(L32*60/Q32)) | T32: =IF(M32>0,N32/M32,"") | U32: =IF(H32>0,R32*S32*T32,"") | V32: =VLOOKUP(D32,Données!$C$2:$E$1300,3,FALSE) -> 4.75 | W32: 0 | X32: =+V32*N32/3600 -> 0 | Y32: =IF(W32=0,"",X32/W32)
A33: 46300 | B33: Nuit | C33: D230.3 | D33: 2.1.30171 | E33: =VLOOKUP(D33,Données!$C$2:$D$1300,2,FALSE) -> Cover KIKO | F33: 480 | G33: 480 | H33: =F33-G33 -> 0 | I33: 0 | K33: 0 | L33: =H33-I33-J33-K33 -> 0 | M33: =+N33+O33+P33 -> 0 | N33: 0 | O33: 0 | P33: 0 | Q33: =VLOOKUP(D33,Données!$C$2:$E$1300,3,FALSE) -> 4.875 | R33: =IF(H33>0,L33/H33,"") | S33: =IF(L33=0,"",M33/(L33*60/Q33)) | T33: =IF(M33>0,N33/M33,"") | U33: =IF(H33>0,R33*S33*T33,"") | V33: =VLOOKUP(D33,Données!$C$2:$E$1300,3,FALSE) -> 4.875 | W33: 0 | X33: =+V33*N33/3600 -> 0 | Y33: =IF(W33=0,"",X33/W33)
A34: 46300 | B34: Matin | C34: D140.1 | D34: 2.1.30173 | E34: =VLOOKUP(D34,Données!$C$2:$D$1300,2,FALSE) -> Insert KIKO | F34: 480 | H34: =F34-G34 -> 480 | I34: 0 | J34: 45 | K34: 0 | L34: =H34-I34-J34-K34 -> 435 | M34: =+N34+O34+P34 -> 3858 | N34: 3854 | O34: 4 | P34: 0 | Q34: =VLOOKUP(D34,Données!$C$2:$E$1300,3,FALSE) -> 3.75 | R34: =IF(H34>0,L34/H34,"") -> 0.90625 | S34: =IF(L34=0,"",M34/(L34*60/Q34)) -> 0.55431034 | T34: =IF(M34>0,N34/M34,"") -> 0.99896319 | U34: =IF(H34>0,R34*S34*T34,"") -> 0.50182292 | V34: =VLOOKUP(D34,Données!$C$2:$E$1300,3,FALSE) -> 3.75 | W34: 8 | X34: =+V34*N34/3600 -> 4.0145833 | Y34: =IF(W34=0,"",X34/W34) -> 0.50182292
A35: 46300 | B35: Matin | C35: D230.1 | D35: 2.1.30172 | E35: =VLOOKUP(D35,Données!$C$2:$D$1300,2,FALSE) -> Base KIKO | F35: 480 | H35: =F35-G35 -> 480 | I35: 0 | J35: 45 | K35: 0 | L35: =H35-I35-J35-K35 -> 435 | M35: =+N35+O35+P35 -> 4539 | N35: 4516 | O35: 23 | P35: 0 | Q35: =VLOOKUP(D35,Données!$C$2:$E$1300,3,FALSE) -> 4.75 | R35: =IF(H35>0,L35/H35,"") -> 0.90625 | S35: =IF(L35=0,"",M35/(L35*60/Q35)) -> 0.82606322 | T35: =IF(M35>0,N35/M35,"") -> 0.9949328 | U35: =IF(H35>0,R35*S35*T35,"") -> 0.74482639 | V35: =VLOOKUP(D35,Données!$C$2:$E$1300,3,FALSE) -> 4.75 | W35: 8 | X35: =+V35*N35/3600 -> 5.9586111 | Y35: =IF(W35=0,"",X35/W35) -> 0.74482639
A36: 46300 | B36: Matin | C36: D230.3 | D36: 2.1.30171 | E36: =VLOOKUP(D36,Données!$C$2:$D$1300,2,FALSE) -> Cover KIKO | F36: 480 | H36: =F36-G36 -> 480 | I36: 0 | J36: 45 | K36: 0 | L36: =H36-I36-J36-K36 -> 435 | M36: =+N36+O36+P36 -> 4360 | N36: 4331 | O36: 29 | P36: 0 | Q36: =VLOOKUP(D36,Données!$C$2:$E$1300,3,FALSE) -> 4.875 | R36: =IF(H36>0,L36/H36,"") -> 0.90625 | S36: =IF(L36=0,"",M36/(L36*60/Q36)) -> 0.81436782 | T36: =IF(M36>0,N36/M36,"") -> 0.99334862 | U36: =IF(H36>0,R36*S36*T36,"") -> 0.73311198 | V36: =VLOOKUP(D36,Données!$C$2:$E$1300,3,FALSE) -> 4.875 | W36: 8 | X36: =+V36*N36/3600 -> 5.8648958 | Y36: =IF(W36=0,"",X36/W36) -> 0.73311198
A37: 46300 | B37: Après-Midi | C37: D140.1 | D37: 2.1.30173 | E37: =VLOOKUP(D37,Données!$C$2:$D$1300,2,FALSE) -> Insert KIKO | F37: 480 | H37: =F37-G37 -> 480 | I37: 0 | J37: 25 | K37: 0 | L37: =H37-I37-J37-K37 -> 455 | M37: =+N37+O37+P37 -> 5984 | N37: 5925 | O37: 59 | P37: 0 | Q37: =VLOOKUP(D37,Données!$C$2:$E$1300,3,FALSE) -> 3.75 | R37: =IF(H37>0,L37/H37,"") -> 0.94791667 | S37: =IF(L37=0,"",M37/(L37*60/Q37)) -> 0.82197802 | T37: =IF(M37>0,N37/M37,"") -> 0.99014037 | U37: =IF(H37>0,R37*S37*T37,"") -> 0.77148437 | V37: =VLOOKUP(D37,Données!$C$2:$E$1300,3,FALSE) -> 3.75 | W37: 8 | X37: =+V37*N37/3600 -> 6.171875 | Y37: =IF(W37=0,"",X37/W37) -> 0.77148438
A38: 46300 | B38: Après-Midi | C38: D230.1 | D38: 2.1.30172 | E38: =VLOOKUP(D38,Données!$C$2:$D$1300,2,FALSE) -> Base KIKO | F38: 480 | H38: =F38-G38 -> 480 | I38: 0 | J38: 25 | K38: 0 | L38: =H38-I38-J38-K38 -> 455 | M38: =+N38+O38+P38 -> 6151 | N38: 6141 | O38: 10 | P38: 0 | Q38: =VLOOKUP(D38,Données!$C$2:$E$1300,3,FALSE) -> 4.75 | R38: =IF(H38>0,L38/H38,"") -> 0.94791667 | S38: =IF(L38=0,"",M38/(L38*60/Q38)) -> 1.0702289 | T38: =IF(M38>0,N38/M38,"") -> 0.99837425 | U38: =IF(H38>0,R38*S38*T38,"") -> 1.0128385 | V38: =VLOOKUP(D38,Données!$C$2:$E$1300,3,FALSE) -> 4.75 | W38: 8 | X38: =+V38*N38/3600 -> 8.1027083 | Y38: =IF(W38=0,"",X38/W38) -> 1.0128385
A39: 46300 | B39: Après-Midi | C39: D230.3 | D39: 2.1.30171 | E39: =VLOOKUP(D39,Données!$C$2:$D$1300,2,FALSE) -> Cover KIKO | F39: 480 | H39: =F39-G39 -> 480 | I39: 0 | J39: 25 | K39: 0 | L39: =H39-I39-J39-K39 -> 455 | M39: =+N39+O39+P39 -> 5952 | N39: 5902 | O39: 50 | P39: 0 | Q39: =VLOOKUP(D39,Données!$C$2:$E$1300,3,FALSE) -> 4.875 | R39: =IF(H39>0,L39/H39,"") -> 0.94791667 | S39: =IF(L39=0,"",M39/(L39*60/Q39)) -> 1.0628571 | T39: =IF(M39>0,N39/M39,"") -> 0.99159946 | U39: =IF(H39>0,R39*S39*T39,"") -> 0.99903646 | V39: =VLOOKUP(D39,Données!$C$2:$E$1300,3,FALSE) -> 4.875 | W39: 8 | X39: =+V39*N39/3600 -> 7.9922917 | Y39: =IF(W39=0,"",X39/W39) -> 0.99903646
A40: 46301 | B40: Nuit | C40: D140.1 | D40: 2.1.30173 | E40: =VLOOKUP(D40,Données!$C$2:$D$1300,2,FALSE) -> Insert KIKO | F40: 480 | G40: 480 | H40: =F40-G40 -> 0 | I40: 0 | K40: 0 | L40: =H40-I40-J40-K40 -> 0 | M40: =+N40+O40+P40 -> 0 | N40: 0 | O40: 0 | P40: 0 | Q40: =VLOOKUP(D40,Données!$C$2:$E$1300,3,FALSE) -> 3.75 | R40: =IF(H40>0,L40/H40,"") | S40: =IF(L40=0,"",M40/(L40*60/Q40)) | T40: =IF(M40>0,N40/M40,"") | U40: =IF(H40>0,R40*S40*T40,"") | V40: =VLOOKUP(D40,Données!$C$2:$E$1300,3,FALSE) -> 3.75 | W40: 0 | X40: =+V40*N40/3600 -> 0 | Y40: =IF(W40=0,"",X40/W40)
A41: 46301 | B41: Nuit | C41: D230.1 | D41: 2.1.30172 | E41: =VLOOKUP(D41,Données!$C$2:$D$1300,2,FALSE) -> Base KIKO | F41: 480 | G41: 480 | H41: =F41-G41 -> 0 | I41: 0 | K41: 0 | L41: =H41-I41-J41-K41 -> 0 | M41: =+N41+O41+P41 -> 0 | N41: 0 | O41: 0 | P41: 0 | Q41: =VLOOKUP(D41,Données!$C$2:$E$1300,3,FALSE) -> 4.75 | R41: =IF(H41>0,L41/H41,"") | S41: =IF(L41=0,"",M41/(L41*60/Q41)) | T41: =IF(M41>0,N41/M41,"") | U41: =IF(H41>0,R41*S41*T41,"") | V41: =VLOOKUP(D41,Données!$C$2:$E$1300,3,FALSE) -> 4.75 | W41: 0 | X41: =+V41*N41/3600 -> 0 | Y41: =IF(W41=0,"",X41/W41)
...

Sheet Dashboard_TRS
A1: TABLEAU DE BORD DE PERFORMANCE - ATELIER INJECTION
A3: Indicateurs Clés de Performance (KPIs Global Ateliers)
A5: TRS MOYEN | C5: DISPONIBILITÉ (Td) | E5: PERFORMANCE (Tp) | G5: QUALITÉ (Tq)
A6: =AVERAGE(Saisie_Donnees!U4:U6) -> #DIV/0! | C6: =AVERAGE(Saisie_Donnees!R4:R6) -> #DIV/0! | E6: =AVERAGE(Saisie_Donnees!S4:S6) -> #DIV/0! | G6: =AVERAGE(Saisie_Donnees!T4:T6) -> #DIV/0!
A9: Performance Détaillée par Presse
A11: N° Presse | B11: Temps Req. (min) | C11: Temps Mach. (min) | D11: Qté Prod (pcs) | E11: Qté Conf (pcs) | F11: Td Moy. | G11: Tp Moy. | H11: Tq Moy. | I11: TRS Moy.
A12: P-01 | B12: =SUMIF(Saisie_Donnees!$C$4:$C$6,A12,Saisie_Donnees!$H$4:$H$6) -> 0 | C12: =SUMIF(Saisie_Donnees!$C$4:$C$6,A12,Saisie_Donnees!$L$4:$L$6) -> 0 | D12: =SUMIF(Saisie_Donnees!$C$4:$C$6,A12,Saisie_Donnees!$M$4:$M$6) -> 0 | E12: =SUMIF(Saisie_Donnees!$C$4:$C$6,A12,Saisie_Donnees!$N$4:$N$6) -> 0 | F12: =AVERAGEIF(Saisie_Donnees!$C$4:$C$6,A12,Saisie_Donnees!$R$4:$R$6) -> #DIV/0! | G12: =AVERAGEIF(Saisie_Donnees!$C$4:$C$6,A12,Saisie_Donnees!$S$4:$S$6) -> #DIV/0! | H12: =AVERAGEIF(Saisie_Donnees!$C$4:$C$6,A12,Saisie_Donnees!$T$4:$T$6) -> #DIV/0! | I12: =AVERAGEIF(Saisie_Donnees!$C$4:$C$6,A12,Saisie_Donnees!$U$4:$U$6) -> #DIV/0!
A13: P-02 | B13: =SUMIF(Saisie_Donnees!$C$4:$C$6,A13,Saisie_Donnees!$H$4:$H$6) -> 0 | C13: =SUMIF(Saisie_Donnees!$C$4:$C$6,A13,Saisie_Donnees!$L$4:$L$6) -> 0 | D13: =SUMIF(Saisie_Donnees!$C$4:$C$6,A13,Saisie_Donnees!$M$4:$M$6) -> 0 | E13: =SUMIF(Saisie_Donnees!$C$4:$C$6,A13,Saisie_Donnees!$N$4:$N$6) -> 0 | F13: =AVERAGEIF(Saisie_Donnees!$C$4:$C$6,A13,Saisie_Donnees!$R$4:$R$6) -> #DIV/0! | G13: =AVERAGEIF(Saisie_Donnees!$C$4:$C$6,A13,Saisie_Donnees!$S$4:$S$6) -> #DIV/0! | H13: =AVERAGEIF(Saisie_Donnees!$C$4:$C$6,A13,Saisie_Donnees!$T$4:$T$6) -> #DIV/0! | I13: =AVERAGEIF(Saisie_Donnees!$C$4:$C$6,A13,Saisie_Donnees!$U$4:$U$6) -> #DIV/0!
A14: P-03 | B14: =SUMIF(Saisie_Donnees!$C$4:$C$6,A14,Saisie_Donnees!$H$4:$H$6) -> 0 | C14: =SUMIF(Saisie_Donnees!$C$4:$C$6,A14,Saisie_Donnees!$L$4:$L$6) -> 0 | D14: =SUMIF(Saisie_Donnees!$C$4:$C$6,A14,Saisie_Donnees!$M$4:$M$6) -> 0 | E14: =SUMIF(Saisie_Donnees!$C$4:$C$6,A14,Saisie_Donnees!$N$4:$N$6) -> 0 | F14: =AVERAGEIF(Saisie_Donnees!$C$4:$C$6,A14,Saisie_Donnees!$R$4:$R$6) -> #DIV/0! | G14: =AVERAGEIF(Saisie_Donnees!$C$4:$C$6,A14,Saisie_Donnees!$S$4:$S$6) -> #DIV/0! | H14: =AVERAGEIF(Saisie_Donnees!$C$4:$C$6,A14,Saisie_Donnees!$T$4:$T$6) -> #DIV/0! | I14: =AVERAGEIF(Saisie_Donnees!$C$4:$C$6,A14,Saisie_Donnees!$U$4:$U$6) -> #DIV/0!
A15: TOTAL / MOYENNE | B15: =SUM(B12:B14) -> 0 | C15: =SUM(C12:C14) -> 0 | D15: =SUM(D12:D14) -> 0 | E15: =SUM(E12:E14) -> 0 | F15: =AVERAGE(F12:F14) -> #DIV/0! | G15: =AVERAGE(G12:G14) -> #DIV/0! | H15: =AVERAGE(H12:H14) -> #DIV/0! | I15: =AVERAGE(I12:I14) -> #DIV/0!

Sheet Parametres_Moules
A1: BASE DE DONNÉES - OUTILLAGES & MOULES
A3: Code Moule | B3: Nom de la Pièce | C3: Nbr Empreintes | D3: Cycle Théo (s)
A4: 2.1.30171 | B4: cover | C4: 8 | D4: 39
A5: 2.1.30172 | B5: BASE | C5: 8 | D5: 38
A6: 2.1.30173 | B6: INSERT | C6: 8 | D6: 30
